2020-01-28 13:35:06,566 INFO: PREdict startup [in /home/rgarcia/Programs/web-projects/testing-site/app/__init__.py:46]
2020-01-28 13:36:11,999 ERROR: Exception on /index [GET] [in /home/rgarcia/.local/lib/python3.6/site-packages/flask/app.py:1891]
Traceback (most recent call last):
  File "/home/rgarcia/.local/lib/python3.6/site-packages/flask/app.py", line 2446, in wsgi_app
    response = self.full_dispatch_request()
  File "/home/rgarcia/.local/lib/python3.6/site-packages/flask/app.py", line 1951, in full_dispatch_request
    rv = self.handle_user_exception(e)
  File "/home/rgarcia/.local/lib/python3.6/site-packages/flask/app.py", line 1820, in handle_user_exception
    reraise(exc_type, exc_value, tb)
  File "/home/rgarcia/.local/lib/python3.6/site-packages/flask/_compat.py", line 39, in reraise
    raise value
  File "/home/rgarcia/.local/lib/python3.6/site-packages/flask/app.py", line 1949, in full_dispatch_request
    rv = self.dispatch_request()
  File "/home/rgarcia/.local/lib/python3.6/site-packages/flask/app.py", line 1935, in dispatch_request
    return self.view_functions[rule.endpoint](**req.view_args)
  File "/home/rgarcia/Programs/web-projects/testing-site/app/routes.py", line 20, in index
    predictions = current_user.followed_predictions().all()
  File "/home/rgarcia/.local/lib/python3.6/site-packages/werkzeug/local.py", line 348, in __getattr__
    return getattr(self._get_current_object(), name)
AttributeError: 'AnonymousUserMixin' object has no attribute 'followed_predictions'
2020-01-28 13:37:21,111 INFO: PREdict startup [in /home/rgarcia/Programs/web-projects/testing-site/app/__init__.py:46]
2020-01-28 13:49:06,507 INFO: PREdict startup [in /home/rgarcia/Programs/web-projects/testing-site/app/__init__.py:46]
2020-01-28 13:49:09,018 ERROR: Exception on / [GET] [in /home/rgarcia/.local/lib/python3.6/site-packages/flask/app.py:1891]
Traceback (most recent call last):
  File "/home/rgarcia/.local/lib/python3.6/site-packages/flask/app.py", line 2446, in wsgi_app
    response = self.full_dispatch_request()
  File "/home/rgarcia/.local/lib/python3.6/site-packages/flask/app.py", line 1951, in full_dispatch_request
    rv = self.handle_user_exception(e)
  File "/home/rgarcia/.local/lib/python3.6/site-packages/flask/app.py", line 1820, in handle_user_exception
    reraise(exc_type, exc_value, tb)
  File "/home/rgarcia/.local/lib/python3.6/site-packages/flask/_compat.py", line 39, in reraise
    raise value
  File "/home/rgarcia/.local/lib/python3.6/site-packages/flask/app.py", line 1949, in full_dispatch_request
    rv = self.dispatch_request()
  File "/home/rgarcia/.local/lib/python3.6/site-packages/flask/app.py", line 1935, in dispatch_request
    return self.view_functions[rule.endpoint](**req.view_args)
  File "/home/rgarcia/Programs/web-projects/testing-site/app/routes.py", line 24, in index
    return render_template('index.html', title='Home', form=form, predictions=predictions)
  File "/home/rgarcia/.local/lib/python3.6/site-packages/flask/templating.py", line 140, in render_template
    ctx.app,
  File "/home/rgarcia/.local/lib/python3.6/site-packages/flask/templating.py", line 120, in _render
    rv = template.render(context)
  File "/home/rgarcia/.local/lib/python3.6/site-packages/jinja2/environment.py", line 1090, in render
    self.environment.handle_exception()
  File "/home/rgarcia/.local/lib/python3.6/site-packages/jinja2/environment.py", line 832, in handle_exception
    reraise(*rewrite_traceback_stack(source=source))
  File "/home/rgarcia/.local/lib/python3.6/site-packages/jinja2/_compat.py", line 28, in reraise
    raise value.with_traceback(tb)
  File "/home/rgarcia/Programs/web-projects/testing-site/app/templates/index.html", line 1, in top-level template code
    {% extends "base.html" %}
  File "/home/rgarcia/Programs/web-projects/testing-site/app/templates/base.html", line 58, in top-level template code
    {% block content %}
  File "/home/rgarcia/Programs/web-projects/testing-site/app/templates/index.html", line 25, in block "content"
    {% include 'base_prediction.html' %}
  File "/home/rgarcia/.local/lib/python3.6/site-packages/flask/templating.py", line 60, in get_source
    return self._get_source_fast(environment, template)
  File "/home/rgarcia/.local/lib/python3.6/site-packages/flask/templating.py", line 89, in _get_source_fast
    raise TemplateNotFound(template)
jinja2.exceptions.TemplateNotFound: base_prediction.html
2020-01-28 13:49:24,721 INFO: PREdict startup [in /home/rgarcia/Programs/web-projects/testing-site/app/__init__.py:46]
2020-01-28 13:49:26,199 ERROR: Exception on / [GET] [in /home/rgarcia/.local/lib/python3.6/site-packages/flask/app.py:1891]
Traceback (most recent call last):
  File "/home/rgarcia/.local/lib/python3.6/site-packages/flask/app.py", line 2446, in wsgi_app
    response = self.full_dispatch_request()
  File "/home/rgarcia/.local/lib/python3.6/site-packages/flask/app.py", line 1951, in full_dispatch_request
    rv = self.handle_user_exception(e)
  File "/home/rgarcia/.local/lib/python3.6/site-packages/flask/app.py", line 1820, in handle_user_exception
    reraise(exc_type, exc_value, tb)
  File "/home/rgarcia/.local/lib/python3.6/site-packages/flask/_compat.py", line 39, in reraise
    raise value
  File "/home/rgarcia/.local/lib/python3.6/site-packages/flask/app.py", line 1949, in full_dispatch_request
    rv = self.dispatch_request()
  File "/home/rgarcia/.local/lib/python3.6/site-packages/flask/app.py", line 1935, in dispatch_request
    return self.view_functions[rule.endpoint](**req.view_args)
  File "/home/rgarcia/Programs/web-projects/testing-site/app/routes.py", line 24, in index
    return render_template('index.html', title='Home', form=form, predictions=predictions)
  File "/home/rgarcia/.local/lib/python3.6/site-packages/flask/templating.py", line 140, in render_template
    ctx.app,
  File "/home/rgarcia/.local/lib/python3.6/site-packages/flask/templating.py", line 120, in _render
    rv = template.render(context)
  File "/home/rgarcia/.local/lib/python3.6/site-packages/jinja2/environment.py", line 1090, in render
    self.environment.handle_exception()
  File "/home/rgarcia/.local/lib/python3.6/site-packages/jinja2/environment.py", line 832, in handle_exception
    reraise(*rewrite_traceback_stack(source=source))
  File "/home/rgarcia/.local/lib/python3.6/site-packages/jinja2/_compat.py", line 28, in reraise
    raise value.with_traceback(tb)
  File "/home/rgarcia/Programs/web-projects/testing-site/app/templates/index.html", line 1, in top-level template code
    {% extends "base.html" %}
  File "/home/rgarcia/Programs/web-projects/testing-site/app/templates/base.html", line 58, in top-level template code
    {% block content %}
  File "/home/rgarcia/Programs/web-projects/testing-site/app/templates/index.html", line 25, in block "content"
    {% include 'prediction_base.html' %}
  File "/home/rgarcia/Programs/web-projects/testing-site/app/templates/prediction_base.html", line 3, in top-level template code
    <td><img src="{{ user.avatar(36) }}"></td>
  File "/home/rgarcia/.local/lib/python3.6/site-packages/jinja2/environment.py", line 471, in getattr
    return getattr(obj, attribute)
jinja2.exceptions.UndefinedError: 'user' is undefined
2020-01-28 13:52:36,880 INFO: PREdict startup [in /home/rgarcia/Programs/web-projects/testing-site/app/__init__.py:46]
2020-01-28 13:52:38,627 ERROR: Exception on / [GET] [in /home/rgarcia/.local/lib/python3.6/site-packages/flask/app.py:1891]
Traceback (most recent call last):
  File "/home/rgarcia/.local/lib/python3.6/site-packages/flask/app.py", line 2446, in wsgi_app
    response = self.full_dispatch_request()
  File "/home/rgarcia/.local/lib/python3.6/site-packages/flask/app.py", line 1951, in full_dispatch_request
    rv = self.handle_user_exception(e)
  File "/home/rgarcia/.local/lib/python3.6/site-packages/flask/app.py", line 1820, in handle_user_exception
    reraise(exc_type, exc_value, tb)
  File "/home/rgarcia/.local/lib/python3.6/site-packages/flask/_compat.py", line 39, in reraise
    raise value
  File "/home/rgarcia/.local/lib/python3.6/site-packages/flask/app.py", line 1949, in full_dispatch_request
    rv = self.dispatch_request()
  File "/home/rgarcia/.local/lib/python3.6/site-packages/flask/app.py", line 1935, in dispatch_request
    return self.view_functions[rule.endpoint](**req.view_args)
  File "/home/rgarcia/Programs/web-projects/testing-site/app/routes.py", line 24, in index
    return render_template('index.html', title='Home', form=form, predictions=predictions)
  File "/home/rgarcia/.local/lib/python3.6/site-packages/flask/templating.py", line 140, in render_template
    ctx.app,
  File "/home/rgarcia/.local/lib/python3.6/site-packages/flask/templating.py", line 120, in _render
    rv = template.render(context)
  File "/home/rgarcia/.local/lib/python3.6/site-packages/jinja2/environment.py", line 1090, in render
    self.environment.handle_exception()
  File "/home/rgarcia/.local/lib/python3.6/site-packages/jinja2/environment.py", line 832, in handle_exception
    reraise(*rewrite_traceback_stack(source=source))
  File "/home/rgarcia/.local/lib/python3.6/site-packages/jinja2/_compat.py", line 28, in reraise
    raise value.with_traceback(tb)
  File "/home/rgarcia/Programs/web-projects/testing-site/app/templates/index.html", line 1, in top-level template code
    {% extends "base.html" %}
  File "/home/rgarcia/Programs/web-projects/testing-site/app/templates/base.html", line 58, in top-level template code
    {% block content %}
  File "/home/rgarcia/Programs/web-projects/testing-site/app/templates/index.html", line 26, in block "content"
    {% include 'prediction_base.html' %}
  File "/home/rgarcia/Programs/web-projects/testing-site/app/templates/prediction_base.html", line 3, in top-level template code
    <td><img src="{{ user.avatar(36) }}"></td>
  File "/home/rgarcia/.local/lib/python3.6/site-packages/jinja2/environment.py", line 471, in getattr
    return getattr(obj, attribute)
jinja2.exceptions.UndefinedError: 'user' is undefined
2020-01-28 13:53:43,184 INFO: PREdict startup [in /home/rgarcia/Programs/web-projects/testing-site/app/__init__.py:46]
