2020-01-29 19:19:43,967 ERROR: Exception on / [GET] [in /home/raymun/.local/share/virtualenvs/Proyectos-TA_eUHkL/lib/python3.5/site-packages/flask/app.py:1891]
Traceback (most recent call last):
  File "/home/raymun/.local/share/virtualenvs/Proyectos-TA_eUHkL/lib/python3.5/site-packages/flask/app.py", line 2446, in wsgi_app
    response = self.full_dispatch_request()
  File "/home/raymun/.local/share/virtualenvs/Proyectos-TA_eUHkL/lib/python3.5/site-packages/flask/app.py", line 1951, in full_dispatch_request
    rv = self.handle_user_exception(e)
  File "/home/raymun/.local/share/virtualenvs/Proyectos-TA_eUHkL/lib/python3.5/site-packages/flask/app.py", line 1820, in handle_user_exception
    reraise(exc_type, exc_value, tb)
  File "/home/raymun/.local/share/virtualenvs/Proyectos-TA_eUHkL/lib/python3.5/site-packages/flask/_compat.py", line 39, in reraise
    raise value
  File "/home/raymun/.local/share/virtualenvs/Proyectos-TA_eUHkL/lib/python3.5/site-packages/flask/app.py", line 1949, in full_dispatch_request
    rv = self.dispatch_request()
  File "/home/raymun/.local/share/virtualenvs/Proyectos-TA_eUHkL/lib/python3.5/site-packages/flask/app.py", line 1935, in dispatch_request
    return self.view_functions[rule.endpoint](**req.view_args)
  File "/home/raymun/Proyectos/WebPages/projects/personal_web_page/app/routes.py", line 21, in index
    next_url=next_url, prev_url=prev_url)
  File "/home/raymun/.local/share/virtualenvs/Proyectos-TA_eUHkL/lib/python3.5/site-packages/flask/templating.py", line 140, in render_template
    ctx.app,
  File "/home/raymun/.local/share/virtualenvs/Proyectos-TA_eUHkL/lib/python3.5/site-packages/flask/templating.py", line 120, in _render
    rv = template.render(context)
  File "/home/raymun/.local/share/virtualenvs/Proyectos-TA_eUHkL/lib/python3.5/site-packages/jinja2/environment.py", line 1090, in render
    self.environment.handle_exception()
  File "/home/raymun/.local/share/virtualenvs/Proyectos-TA_eUHkL/lib/python3.5/site-packages/jinja2/environment.py", line 832, in handle_exception
    reraise(*rewrite_traceback_stack(source=source))
  File "/home/raymun/.local/share/virtualenvs/Proyectos-TA_eUHkL/lib/python3.5/site-packages/jinja2/_compat.py", line 28, in reraise
    raise value.with_traceback(tb)
  File "/home/raymun/Proyectos/WebPages/projects/personal_web_page/app/templates/index.html", line 1, in top-level template code
    {% extends "base.html" %}
  File "/home/raymun/Proyectos/WebPages/projects/personal_web_page/app/templates/base.html", line 58, in top-level template code
    {% block content %}
  File "/home/raymun/Proyectos/WebPages/projects/personal_web_page/app/templates/index.html", line 12, in block "content"
    {% include 'prediction_base.html' %}
  File "/home/raymun/Proyectos/WebPages/projects/personal_web_page/app/templates/prediction_base.html", line 10, in top-level template code
    {{ moment(post.timestamp).fromNow() }}:</div>
  File "/home/raymun/.local/share/virtualenvs/Proyectos-TA_eUHkL/lib/python3.5/site-packages/jinja2/environment.py", line 471, in getattr
    return getattr(obj, attribute)
jinja2.exceptions.UndefinedError: 'post' is undefined
2020-01-29 19:19:52,792 ERROR: Exception on /index [GET] [in /home/raymun/.local/share/virtualenvs/Proyectos-TA_eUHkL/lib/python3.5/site-packages/flask/app.py:1891]
Traceback (most recent call last):
  File "/home/raymun/.local/share/virtualenvs/Proyectos-TA_eUHkL/lib/python3.5/site-packages/flask/app.py", line 2446, in wsgi_app
    response = self.full_dispatch_request()
  File "/home/raymun/.local/share/virtualenvs/Proyectos-TA_eUHkL/lib/python3.5/site-packages/flask/app.py", line 1951, in full_dispatch_request
    rv = self.handle_user_exception(e)
  File "/home/raymun/.local/share/virtualenvs/Proyectos-TA_eUHkL/lib/python3.5/site-packages/flask/app.py", line 1820, in handle_user_exception
    reraise(exc_type, exc_value, tb)
  File "/home/raymun/.local/share/virtualenvs/Proyectos-TA_eUHkL/lib/python3.5/site-packages/flask/_compat.py", line 39, in reraise
    raise value
  File "/home/raymun/.local/share/virtualenvs/Proyectos-TA_eUHkL/lib/python3.5/site-packages/flask/app.py", line 1949, in full_dispatch_request
    rv = self.dispatch_request()
  File "/home/raymun/.local/share/virtualenvs/Proyectos-TA_eUHkL/lib/python3.5/site-packages/flask/app.py", line 1935, in dispatch_request
    return self.view_functions[rule.endpoint](**req.view_args)
  File "/home/raymun/Proyectos/WebPages/projects/personal_web_page/app/routes.py", line 21, in index
    next_url=next_url, prev_url=prev_url)
  File "/home/raymun/.local/share/virtualenvs/Proyectos-TA_eUHkL/lib/python3.5/site-packages/flask/templating.py", line 140, in render_template
    ctx.app,
  File "/home/raymun/.local/share/virtualenvs/Proyectos-TA_eUHkL/lib/python3.5/site-packages/flask/templating.py", line 120, in _render
    rv = template.render(context)
  File "/home/raymun/.local/share/virtualenvs/Proyectos-TA_eUHkL/lib/python3.5/site-packages/jinja2/environment.py", line 1090, in render
    self.environment.handle_exception()
  File "/home/raymun/.local/share/virtualenvs/Proyectos-TA_eUHkL/lib/python3.5/site-packages/jinja2/environment.py", line 832, in handle_exception
    reraise(*rewrite_traceback_stack(source=source))
  File "/home/raymun/.local/share/virtualenvs/Proyectos-TA_eUHkL/lib/python3.5/site-packages/jinja2/_compat.py", line 28, in reraise
    raise value.with_traceback(tb)
  File "/home/raymun/Proyectos/WebPages/projects/personal_web_page/app/templates/index.html", line 1, in top-level template code
    {% extends "base.html" %}
  File "/home/raymun/Proyectos/WebPages/projects/personal_web_page/app/templates/base.html", line 58, in top-level template code
    {% block content %}
  File "/home/raymun/Proyectos/WebPages/projects/personal_web_page/app/templates/index.html", line 12, in block "content"
    {% include 'prediction_base.html' %}
  File "/home/raymun/Proyectos/WebPages/projects/personal_web_page/app/templates/prediction_base.html", line 10, in top-level template code
    {{ moment(post.timestamp).fromNow() }}:</div>
  File "/home/raymun/.local/share/virtualenvs/Proyectos-TA_eUHkL/lib/python3.5/site-packages/jinja2/environment.py", line 471, in getattr
    return getattr(obj, attribute)
jinja2.exceptions.UndefinedError: 'post' is undefined
2020-01-29 19:22:03,579 INFO: PREdict startup [in /home/raymun/Proyectos/WebPages/projects/personal_web_page/app/__init__.py:50]
2020-01-29 19:23:00,363 INFO: PREdict startup [in /home/raymun/Proyectos/WebPages/projects/personal_web_page/app/__init__.py:50]
2020-01-29 19:23:55,488 INFO: PREdict startup [in /home/raymun/Proyectos/WebPages/projects/personal_web_page/app/__init__.py:50]
2020-01-29 21:13:07,568 INFO: PREdict startup [in /home/raymun/Proyectos/WebPages/projects/personal_web_page/app/__init__.py:51]
2020-01-29 21:13:12,076 ERROR: Exception on / [GET] [in /home/raymun/.local/share/virtualenvs/Proyectos-TA_eUHkL/lib/python3.5/site-packages/flask/app.py:1891]
Traceback (most recent call last):
  File "/home/raymun/.local/share/virtualenvs/Proyectos-TA_eUHkL/lib/python3.5/site-packages/flask/app.py", line 2446, in wsgi_app
    response = self.full_dispatch_request()
  File "/home/raymun/.local/share/virtualenvs/Proyectos-TA_eUHkL/lib/python3.5/site-packages/flask/app.py", line 1951, in full_dispatch_request
    rv = self.handle_user_exception(e)
  File "/home/raymun/.local/share/virtualenvs/Proyectos-TA_eUHkL/lib/python3.5/site-packages/flask/app.py", line 1820, in handle_user_exception
    reraise(exc_type, exc_value, tb)
  File "/home/raymun/.local/share/virtualenvs/Proyectos-TA_eUHkL/lib/python3.5/site-packages/flask/_compat.py", line 39, in reraise
    raise value
  File "/home/raymun/.local/share/virtualenvs/Proyectos-TA_eUHkL/lib/python3.5/site-packages/flask/app.py", line 1949, in full_dispatch_request
    rv = self.dispatch_request()
  File "/home/raymun/.local/share/virtualenvs/Proyectos-TA_eUHkL/lib/python3.5/site-packages/flask/app.py", line 1935, in dispatch_request
    return self.view_functions[rule.endpoint](**req.view_args)
  File "/home/raymun/Proyectos/WebPages/projects/personal_web_page/app/routes.py", line 23, in index
    next_url=next_url, prev_url=prev_url)
  File "/home/raymun/.local/share/virtualenvs/Proyectos-TA_eUHkL/lib/python3.5/site-packages/flask/templating.py", line 138, in render_template
    ctx.app.jinja_env.get_or_select_template(template_name_or_list),
  File "/home/raymun/.local/share/virtualenvs/Proyectos-TA_eUHkL/lib/python3.5/site-packages/jinja2/environment.py", line 930, in get_or_select_template
    return self.get_template(template_name_or_list, parent, globals)
  File "/home/raymun/.local/share/virtualenvs/Proyectos-TA_eUHkL/lib/python3.5/site-packages/jinja2/environment.py", line 883, in get_template
    return self._load_template(name, self.make_globals(globals))
  File "/home/raymun/.local/share/virtualenvs/Proyectos-TA_eUHkL/lib/python3.5/site-packages/jinja2/environment.py", line 857, in _load_template
    template = self.loader.load(self, name, globals)
  File "/home/raymun/.local/share/virtualenvs/Proyectos-TA_eUHkL/lib/python3.5/site-packages/jinja2/loaders.py", line 129, in load
    code = environment.compile(source, name, filename)
  File "/home/raymun/.local/share/virtualenvs/Proyectos-TA_eUHkL/lib/python3.5/site-packages/jinja2/environment.py", line 638, in compile
    self.handle_exception(source=source_hint)
  File "/home/raymun/.local/share/virtualenvs/Proyectos-TA_eUHkL/lib/python3.5/site-packages/jinja2/environment.py", line 832, in handle_exception
    reraise(*rewrite_traceback_stack(source=source))
  File "/home/raymun/.local/share/virtualenvs/Proyectos-TA_eUHkL/lib/python3.5/site-packages/jinja2/_compat.py", line 28, in reraise
    raise value.with_traceback(tb)
  File "/home/raymun/Proyectos/WebPages/projects/personal_web_page/app/templates/index.html", line 12, in template
    {% include 'prediction_base.html' %}
jinja2.exceptions.TemplateSyntaxError: expected token ',', got 'prediction_base'
