2020-01-29 19:17:47,681 ERROR: Exception on /explore [GET] [in /home/raymun/.local/share/virtualenvs/Proyectos-TA_eUHkL/lib/python3.5/site-packages/flask/app.py:1891]
Traceback (most recent call last):
  File "/home/raymun/.local/share/virtualenvs/Proyectos-TA_eUHkL/lib/python3.5/site-packages/flask/app.py", line 2446, in wsgi_app
    response = self.full_dispatch_request()
  File "/home/raymun/.local/share/virtualenvs/Proyectos-TA_eUHkL/lib/python3.5/site-packages/flask/app.py", line 1951, in full_dispatch_request
    rv = self.handle_user_exception(e)
  File "/home/raymun/.local/share/virtualenvs/Proyectos-TA_eUHkL/lib/python3.5/site-packages/flask/app.py", line 1820, in handle_user_exception
    reraise(exc_type, exc_value, tb)
  File "/home/raymun/.local/share/virtualenvs/Proyectos-TA_eUHkL/lib/python3.5/site-packages/flask/_compat.py", line 39, in reraise
    raise value
  File "/home/raymun/.local/share/virtualenvs/Proyectos-TA_eUHkL/lib/python3.5/site-packages/flask/app.py", line 1949, in full_dispatch_request
    rv = self.dispatch_request()
  File "/home/raymun/.local/share/virtualenvs/Proyectos-TA_eUHkL/lib/python3.5/site-packages/flask/app.py", line 1935, in dispatch_request
    return self.view_functions[rule.endpoint](**req.view_args)
  File "/home/raymun/.local/share/virtualenvs/Proyectos-TA_eUHkL/lib/python3.5/site-packages/flask_login/utils.py", line 261, in decorated_view
    return func(*args, **kwargs)
  File "/home/raymun/Proyectos/WebPages/projects/personal_web_page/app/routes.py", line 181, in explore
    next_url=next_url, prev_url=prev_url)
  File "/home/raymun/.local/share/virtualenvs/Proyectos-TA_eUHkL/lib/python3.5/site-packages/flask/templating.py", line 140, in render_template
    ctx.app,
  File "/home/raymun/.local/share/virtualenvs/Proyectos-TA_eUHkL/lib/python3.5/site-packages/flask/templating.py", line 120, in _render
    rv = template.render(context)
  File "/home/raymun/.local/share/virtualenvs/Proyectos-TA_eUHkL/lib/python3.5/site-packages/jinja2/environment.py", line 1090, in render
    self.environment.handle_exception()
  File "/home/raymun/.local/share/virtualenvs/Proyectos-TA_eUHkL/lib/python3.5/site-packages/jinja2/environment.py", line 832, in handle_exception
    reraise(*rewrite_traceback_stack(source=source))
  File "/home/raymun/.local/share/virtualenvs/Proyectos-TA_eUHkL/lib/python3.5/site-packages/jinja2/_compat.py", line 28, in reraise
    raise value.with_traceback(tb)
  File "/home/raymun/Proyectos/WebPages/projects/personal_web_page/app/templates/explore.html", line 1, in top-level template code
    {% extends "base.html" %}
  File "/home/raymun/Proyectos/WebPages/projects/personal_web_page/app/templates/base.html", line 58, in top-level template code
    {% block content %}
  File "/home/raymun/Proyectos/WebPages/projects/personal_web_page/app/templates/explore.html", line 30, in block "content"
    {% include 'prediction_base.html' %}
  File "/home/raymun/Proyectos/WebPages/projects/personal_web_page/app/templates/prediction_base.html", line 10, in top-level template code
    {{ moment(post.timestamp).fromNow() }}:</div>
  File "/home/raymun/.local/share/virtualenvs/Proyectos-TA_eUHkL/lib/python3.5/site-packages/jinja2/environment.py", line 471, in getattr
    return getattr(obj, attribute)
jinja2.exceptions.UndefinedError: 'post' is undefined
2020-01-29 19:19:36,100 INFO: PREdict startup [in /home/raymun/Proyectos/WebPages/projects/personal_web_page/app/__init__.py:50]
2020-01-29 19:19:36,397 ERROR: Exception on /explore [GET] [in /home/raymun/.local/share/virtualenvs/Proyectos-TA_eUHkL/lib/python3.5/site-packages/flask/app.py:1891]
Traceback (most recent call last):
  File "/home/raymun/.local/share/virtualenvs/Proyectos-TA_eUHkL/lib/python3.5/site-packages/flask/app.py", line 2446, in wsgi_app
    response = self.full_dispatch_request()
  File "/home/raymun/.local/share/virtualenvs/Proyectos-TA_eUHkL/lib/python3.5/site-packages/flask/app.py", line 1951, in full_dispatch_request
    rv = self.handle_user_exception(e)
  File "/home/raymun/.local/share/virtualenvs/Proyectos-TA_eUHkL/lib/python3.5/site-packages/flask/app.py", line 1820, in handle_user_exception
    reraise(exc_type, exc_value, tb)
  File "/home/raymun/.local/share/virtualenvs/Proyectos-TA_eUHkL/lib/python3.5/site-packages/flask/_compat.py", line 39, in reraise
    raise value
  File "/home/raymun/.local/share/virtualenvs/Proyectos-TA_eUHkL/lib/python3.5/site-packages/flask/app.py", line 1949, in full_dispatch_request
    rv = self.dispatch_request()
  File "/home/raymun/.local/share/virtualenvs/Proyectos-TA_eUHkL/lib/python3.5/site-packages/flask/app.py", line 1935, in dispatch_request
    return self.view_functions[rule.endpoint](**req.view_args)
  File "/home/raymun/.local/share/virtualenvs/Proyectos-TA_eUHkL/lib/python3.5/site-packages/flask_login/utils.py", line 261, in decorated_view
    return func(*args, **kwargs)
  File "/home/raymun/Proyectos/WebPages/projects/personal_web_page/app/routes.py", line 181, in explore
    next_url=next_url, prev_url=prev_url)
  File "/home/raymun/.local/share/virtualenvs/Proyectos-TA_eUHkL/lib/python3.5/site-packages/flask/templating.py", line 140, in render_template
    ctx.app,
  File "/home/raymun/.local/share/virtualenvs/Proyectos-TA_eUHkL/lib/python3.5/site-packages/flask/templating.py", line 120, in _render
    rv = template.render(context)
  File "/home/raymun/.local/share/virtualenvs/Proyectos-TA_eUHkL/lib/python3.5/site-packages/jinja2/environment.py", line 1090, in render
    self.environment.handle_exception()
  File "/home/raymun/.local/share/virtualenvs/Proyectos-TA_eUHkL/lib/python3.5/site-packages/jinja2/environment.py", line 832, in handle_exception
    reraise(*rewrite_traceback_stack(source=source))
  File "/home/raymun/.local/share/virtualenvs/Proyectos-TA_eUHkL/lib/python3.5/site-packages/jinja2/_compat.py", line 28, in reraise
    raise value.with_traceback(tb)
  File "/home/raymun/Proyectos/WebPages/projects/personal_web_page/app/templates/explore.html", line 1, in top-level template code
    {% extends "base.html" %}
  File "/home/raymun/Proyectos/WebPages/projects/personal_web_page/app/templates/base.html", line 58, in top-level template code
    {% block content %}
  File "/home/raymun/Proyectos/WebPages/projects/personal_web_page/app/templates/explore.html", line 29, in block "content"
    {% include 'prediction_base.html' %}
  File "/home/raymun/Proyectos/WebPages/projects/personal_web_page/app/templates/prediction_base.html", line 10, in top-level template code
    {{ moment(post.timestamp).fromNow() }}:</div>
  File "/home/raymun/.local/share/virtualenvs/Proyectos-TA_eUHkL/lib/python3.5/site-packages/jinja2/environment.py", line 471, in getattr
    return getattr(obj, attribute)
jinja2.exceptions.UndefinedError: 'post' is undefined
2020-01-29 19:19:41,895 ERROR: Exception on / [GET] [in /home/raymun/.local/share/virtualenvs/Proyectos-TA_eUHkL/lib/python3.5/site-packages/flask/app.py:1891]
Traceback (most recent call last):
  File "/home/raymun/.local/share/virtualenvs/Proyectos-TA_eUHkL/lib/python3.5/site-packages/flask/app.py", line 2446, in wsgi_app
    response = self.full_dispatch_request()
  File "/home/raymun/.local/share/virtualenvs/Proyectos-TA_eUHkL/lib/python3.5/site-packages/flask/app.py", line 1951, in full_dispatch_request
    rv = self.handle_user_exception(e)
  File "/home/raymun/.local/share/virtualenvs/Proyectos-TA_eUHkL/lib/python3.5/site-packages/flask/app.py", line 1820, in handle_user_exception
    reraise(exc_type, exc_value, tb)
  File "/home/raymun/.local/share/virtualenvs/Proyectos-TA_eUHkL/lib/python3.5/site-packages/flask/_compat.py", line 39, in reraise
    raise value
  File "/home/raymun/.local/share/virtualenvs/Proyectos-TA_eUHkL/lib/python3.5/site-packages/flask/app.py", line 1949, in full_dispatch_request
    rv = self.dispatch_request()
  File "/home/raymun/.local/share/virtualenvs/Proyectos-TA_eUHkL/lib/python3.5/site-packages/flask/app.py", line 1935, in dispatch_request
    return self.view_functions[rule.endpoint](**req.view_args)
  File "/home/raymun/Proyectos/WebPages/projects/personal_web_page/app/routes.py", line 21, in index
    next_url=next_url, prev_url=prev_url)
  File "/home/raymun/.local/share/virtualenvs/Proyectos-TA_eUHkL/lib/python3.5/site-packages/flask/templating.py", line 140, in render_template
    ctx.app,
  File "/home/raymun/.local/share/virtualenvs/Proyectos-TA_eUHkL/lib/python3.5/site-packages/flask/templating.py", line 120, in _render
    rv = template.render(context)
  File "/home/raymun/.local/share/virtualenvs/Proyectos-TA_eUHkL/lib/python3.5/site-packages/jinja2/environment.py", line 1090, in render
    self.environment.handle_exception()
  File "/home/raymun/.local/share/virtualenvs/Proyectos-TA_eUHkL/lib/python3.5/site-packages/jinja2/environment.py", line 832, in handle_exception
    reraise(*rewrite_traceback_stack(source=source))
  File "/home/raymun/.local/share/virtualenvs/Proyectos-TA_eUHkL/lib/python3.5/site-packages/jinja2/_compat.py", line 28, in reraise
    raise value.with_traceback(tb)
  File "/home/raymun/Proyectos/WebPages/projects/personal_web_page/app/templates/index.html", line 1, in top-level template code
    {% extends "base.html" %}
  File "/home/raymun/Proyectos/WebPages/projects/personal_web_page/app/templates/base.html", line 58, in top-level template code
    {% block content %}
  File "/home/raymun/Proyectos/WebPages/projects/personal_web_page/app/templates/index.html", line 12, in block "content"
    {% include 'prediction_base.html' %}
  File "/home/raymun/Proyectos/WebPages/projects/personal_web_page/app/templates/prediction_base.html", line 10, in top-level template code
    {{ moment(post.timestamp).fromNow() }}:</div>
  File "/home/raymun/.local/share/virtualenvs/Proyectos-TA_eUHkL/lib/python3.5/site-packages/jinja2/environment.py", line 471, in getattr
    return getattr(obj, attribute)
jinja2.exceptions.UndefinedError: 'post' is undefined
