2020-01-28 13:00:11,475 ERROR: Exception on / [GET] [in /home/rgarcia/.local/lib/python3.6/site-packages/flask/app.py:1891]
Traceback (most recent call last):
  File "/home/rgarcia/.local/lib/python3.6/site-packages/flask/app.py", line 2446, in wsgi_app
    response = self.full_dispatch_request()
  File "/home/rgarcia/.local/lib/python3.6/site-packages/flask/app.py", line 1951, in full_dispatch_request
    rv = self.handle_user_exception(e)
  File "/home/rgarcia/.local/lib/python3.6/site-packages/flask/app.py", line 1820, in handle_user_exception
    reraise(exc_type, exc_value, tb)
  File "/home/rgarcia/.local/lib/python3.6/site-packages/flask/_compat.py", line 39, in reraise
    raise value
  File "/home/rgarcia/.local/lib/python3.6/site-packages/flask/app.py", line 1949, in full_dispatch_request
    rv = self.dispatch_request()
  File "/home/rgarcia/.local/lib/python3.6/site-packages/flask/app.py", line 1935, in dispatch_request
    return self.view_functions[rule.endpoint](**req.view_args)
  File "/home/rgarcia/Programs/web-projects/testing-site/app/routes.py", line 26, in index
    return render_template('index.html', title='Home', predictions=predictions, user=current_user or None)
  File "/home/rgarcia/.local/lib/python3.6/site-packages/flask/templating.py", line 140, in render_template
    ctx.app,
  File "/home/rgarcia/.local/lib/python3.6/site-packages/flask/templating.py", line 120, in _render
    rv = template.render(context)
  File "/home/rgarcia/.local/lib/python3.6/site-packages/jinja2/environment.py", line 1090, in render
    self.environment.handle_exception()
  File "/home/rgarcia/.local/lib/python3.6/site-packages/jinja2/environment.py", line 832, in handle_exception
    reraise(*rewrite_traceback_stack(source=source))
  File "/home/rgarcia/.local/lib/python3.6/site-packages/jinja2/_compat.py", line 28, in reraise
    raise value.with_traceback(tb)
  File "/home/rgarcia/Programs/web-projects/testing-site/app/templates/index.html", line 1, in top-level template code
    {% extends "base.html" %}
  File "/home/rgarcia/Programs/web-projects/testing-site/app/templates/base.html", line 58, in top-level template code
    {% block content %}
  File "/home/rgarcia/Programs/web-projects/testing-site/app/templates/index.html", line 8, in block "content"
    {{ form.hidden_tag() }}
  File "/home/rgarcia/.local/lib/python3.6/site-packages/jinja2/environment.py", line 471, in getattr
    return getattr(obj, attribute)
jinja2.exceptions.UndefinedError: 'form' is undefined
2020-01-28 13:02:56,074 INFO: PREdict startup [in /home/rgarcia/Programs/web-projects/testing-site/app/__init__.py:46]
2020-01-28 13:07:07,552 INFO: PREdict startup [in /home/rgarcia/Programs/web-projects/testing-site/app/__init__.py:46]
2020-01-28 13:07:19,323 ERROR: Exception on /index [GET] [in /home/rgarcia/.local/lib/python3.6/site-packages/flask/app.py:1891]
Traceback (most recent call last):
  File "/home/rgarcia/.local/lib/python3.6/site-packages/flask/app.py", line 2446, in wsgi_app
    response = self.full_dispatch_request()
  File "/home/rgarcia/.local/lib/python3.6/site-packages/flask/app.py", line 1951, in full_dispatch_request
    rv = self.handle_user_exception(e)
  File "/home/rgarcia/.local/lib/python3.6/site-packages/flask/app.py", line 1820, in handle_user_exception
    reraise(exc_type, exc_value, tb)
  File "/home/rgarcia/.local/lib/python3.6/site-packages/flask/_compat.py", line 39, in reraise
    raise value
  File "/home/rgarcia/.local/lib/python3.6/site-packages/flask/app.py", line 1949, in full_dispatch_request
    rv = self.dispatch_request()
  File "/home/rgarcia/.local/lib/python3.6/site-packages/flask/app.py", line 1935, in dispatch_request
    return self.view_functions[rule.endpoint](**req.view_args)
  File "/home/rgarcia/Programs/web-projects/testing-site/app/routes.py", line 27, in index
    return render_template('index.html', title='Home', predictions=predictions)
  File "/home/rgarcia/.local/lib/python3.6/site-packages/flask/templating.py", line 140, in render_template
    ctx.app,
  File "/home/rgarcia/.local/lib/python3.6/site-packages/flask/templating.py", line 120, in _render
    rv = template.render(context)
  File "/home/rgarcia/.local/lib/python3.6/site-packages/jinja2/environment.py", line 1090, in render
    self.environment.handle_exception()
  File "/home/rgarcia/.local/lib/python3.6/site-packages/jinja2/environment.py", line 832, in handle_exception
    reraise(*rewrite_traceback_stack(source=source))
  File "/home/rgarcia/.local/lib/python3.6/site-packages/jinja2/_compat.py", line 28, in reraise
    raise value.with_traceback(tb)
  File "/home/rgarcia/Programs/web-projects/testing-site/app/templates/index.html", line 1, in top-level template code
    {% extends "base.html" %}
  File "/home/rgarcia/Programs/web-projects/testing-site/app/templates/base.html", line 58, in top-level template code
    {% block content %}
  File "/home/rgarcia/Programs/web-projects/testing-site/app/templates/index.html", line 8, in block "content"
    {{ form.hidden_tag() }}
  File "/home/rgarcia/.local/lib/python3.6/site-packages/jinja2/environment.py", line 471, in getattr
    return getattr(obj, attribute)
jinja2.exceptions.UndefinedError: 'form' is undefined
2020-01-28 13:09:20,706 INFO: PREdict startup [in /home/rgarcia/Programs/web-projects/testing-site/app/__init__.py:46]
2020-01-28 13:24:20,593 INFO: PREdict startup [in /home/rgarcia/Programs/web-projects/testing-site/app/__init__.py:46]
2020-01-28 13:24:23,632 ERROR: Exception on / [GET] [in /home/rgarcia/.local/lib/python3.6/site-packages/flask/app.py:1891]
Traceback (most recent call last):
  File "/home/rgarcia/.local/lib/python3.6/site-packages/flask/app.py", line 2446, in wsgi_app
    response = self.full_dispatch_request()
  File "/home/rgarcia/.local/lib/python3.6/site-packages/flask/app.py", line 1951, in full_dispatch_request
    rv = self.handle_user_exception(e)
  File "/home/rgarcia/.local/lib/python3.6/site-packages/flask/app.py", line 1820, in handle_user_exception
    reraise(exc_type, exc_value, tb)
  File "/home/rgarcia/.local/lib/python3.6/site-packages/flask/_compat.py", line 39, in reraise
    raise value
  File "/home/rgarcia/.local/lib/python3.6/site-packages/flask/app.py", line 1949, in full_dispatch_request
    rv = self.dispatch_request()
  File "/home/rgarcia/.local/lib/python3.6/site-packages/flask/app.py", line 1935, in dispatch_request
    return self.view_functions[rule.endpoint](**req.view_args)
  File "/home/rgarcia/Programs/web-projects/testing-site/app/routes.py", line 20, in index
    predictions = current_user.followed_posts().all()
  File "/home/rgarcia/.local/lib/python3.6/site-packages/werkzeug/local.py", line 348, in __getattr__
    return getattr(self._get_current_object(), name)
AttributeError: 'User' object has no attribute 'followed_posts'
2020-01-28 13:25:51,117 INFO: PREdict startup [in /home/rgarcia/Programs/web-projects/testing-site/app/__init__.py:46]
2020-01-28 13:25:53,129 ERROR: Exception on / [GET] [in /home/rgarcia/.local/lib/python3.6/site-packages/flask/app.py:1891]
Traceback (most recent call last):
  File "/home/rgarcia/.local/lib/python3.6/site-packages/flask/app.py", line 2446, in wsgi_app
    response = self.full_dispatch_request()
  File "/home/rgarcia/.local/lib/python3.6/site-packages/flask/app.py", line 1951, in full_dispatch_request
    rv = self.handle_user_exception(e)
  File "/home/rgarcia/.local/lib/python3.6/site-packages/flask/app.py", line 1820, in handle_user_exception
    reraise(exc_type, exc_value, tb)
  File "/home/rgarcia/.local/lib/python3.6/site-packages/flask/_compat.py", line 39, in reraise
    raise value
  File "/home/rgarcia/.local/lib/python3.6/site-packages/flask/app.py", line 1949, in full_dispatch_request
    rv = self.dispatch_request()
  File "/home/rgarcia/.local/lib/python3.6/site-packages/flask/app.py", line 1935, in dispatch_request
    return self.view_functions[rule.endpoint](**req.view_args)
  File "/home/rgarcia/Programs/web-projects/testing-site/app/routes.py", line 21, in index
    return render_template('index.html', title='Home', form=form, predictions=predictions)
  File "/home/rgarcia/.local/lib/python3.6/site-packages/flask/templating.py", line 138, in render_template
    ctx.app.jinja_env.get_or_select_template(template_name_or_list),
  File "/home/rgarcia/.local/lib/python3.6/site-packages/jinja2/environment.py", line 930, in get_or_select_template
    return self.get_template(template_name_or_list, parent, globals)
  File "/home/rgarcia/.local/lib/python3.6/site-packages/jinja2/environment.py", line 883, in get_template
    return self._load_template(name, self.make_globals(globals))
  File "/home/rgarcia/.local/lib/python3.6/site-packages/jinja2/environment.py", line 857, in _load_template
    template = self.loader.load(self, name, globals)
  File "/home/rgarcia/.local/lib/python3.6/site-packages/jinja2/loaders.py", line 129, in load
    code = environment.compile(source, name, filename)
  File "/home/rgarcia/.local/lib/python3.6/site-packages/jinja2/environment.py", line 638, in compile
    self.handle_exception(source=source_hint)
  File "/home/rgarcia/.local/lib/python3.6/site-packages/jinja2/environment.py", line 832, in handle_exception
    reraise(*rewrite_traceback_stack(source=source))
  File "/home/rgarcia/.local/lib/python3.6/site-packages/jinja2/_compat.py", line 28, in reraise
    raise value.with_traceback(tb)
  File "/home/rgarcia/Programs/web-projects/testing-site/app/templates/index.html", line 88, in template
    {% endblock %}
jinja2.exceptions.TemplateSyntaxError: Encountered unknown tag 'endblock'. You probably made a nesting mistake. Jinja is expecting this tag, but currently looking for 'endif'. The innermost block that needs to be closed is 'if'.
2020-01-28 13:27:58,231 INFO: PREdict startup [in /home/rgarcia/Programs/web-projects/testing-site/app/__init__.py:46]
2020-01-28 13:33:58,588 INFO: PREdict startup [in /home/rgarcia/Programs/web-projects/testing-site/app/__init__.py:46]
2020-01-28 13:34:38,121 INFO: PREdict startup [in /home/rgarcia/Programs/web-projects/testing-site/app/__init__.py:46]
