2020-01-28 10:48:31,690 INFO: PREdict startup [in /home/rgarcia/Programs/web-projects/testing-site/app/__init__.py:46]
2020-01-28 10:49:00,580 ERROR: Exception on /edit_profile [POST] [in /home/rgarcia/.local/lib/python3.6/site-packages/flask/app.py:1891]
Traceback (most recent call last):
  File "/home/rgarcia/.local/lib/python3.6/site-packages/sqlalchemy/engine/base.py", line 1246, in _execute_context
    cursor, statement, parameters, context
  File "/home/rgarcia/.local/lib/python3.6/site-packages/sqlalchemy/engine/default.py", line 588, in do_execute
    cursor.execute(statement, parameters)
psycopg2.IntegrityError: llave duplicada viola restricción de unicidad «ix_user_username»
DETAIL:  Ya existe la llave (username)=(Reymon).


The above exception was the direct cause of the following exception:

Traceback (most recent call last):
  File "/home/rgarcia/.local/lib/python3.6/site-packages/flask/app.py", line 2446, in wsgi_app
    response = self.full_dispatch_request()
  File "/home/rgarcia/.local/lib/python3.6/site-packages/flask/app.py", line 1951, in full_dispatch_request
    rv = self.handle_user_exception(e)
  File "/home/rgarcia/.local/lib/python3.6/site-packages/flask/app.py", line 1820, in handle_user_exception
    reraise(exc_type, exc_value, tb)
  File "/home/rgarcia/.local/lib/python3.6/site-packages/flask/_compat.py", line 39, in reraise
    raise value
  File "/home/rgarcia/.local/lib/python3.6/site-packages/flask/app.py", line 1949, in full_dispatch_request
    rv = self.dispatch_request()
  File "/home/rgarcia/.local/lib/python3.6/site-packages/flask/app.py", line 1935, in dispatch_request
    return self.view_functions[rule.endpoint](**req.view_args)
  File "/home/rgarcia/.local/lib/python3.6/site-packages/flask_login/utils.py", line 261, in decorated_view
    return func(*args, **kwargs)
  File "/home/rgarcia/Programs/web-projects/testing-site/app/routes.py", line 91, in edit_profile
    db.session.commit()
  File "/home/rgarcia/.local/lib/python3.6/site-packages/sqlalchemy/orm/scoping.py", line 162, in do
    return getattr(self.registry(), name)(*args, **kwargs)
  File "/home/rgarcia/.local/lib/python3.6/site-packages/sqlalchemy/orm/session.py", line 1036, in commit
    self.transaction.commit()
  File "/home/rgarcia/.local/lib/python3.6/site-packages/sqlalchemy/orm/session.py", line 503, in commit
    self._prepare_impl()
  File "/home/rgarcia/.local/lib/python3.6/site-packages/sqlalchemy/orm/session.py", line 482, in _prepare_impl
    self.session.flush()
  File "/home/rgarcia/.local/lib/python3.6/site-packages/sqlalchemy/orm/session.py", line 2479, in flush
    self._flush(objects)
  File "/home/rgarcia/.local/lib/python3.6/site-packages/sqlalchemy/orm/session.py", line 2617, in _flush
    transaction.rollback(_capture_exception=True)
  File "/home/rgarcia/.local/lib/python3.6/site-packages/sqlalchemy/util/langhelpers.py", line 68, in __exit__
    compat.reraise(exc_type, exc_value, exc_tb)
  File "/home/rgarcia/.local/lib/python3.6/site-packages/sqlalchemy/util/compat.py", line 153, in reraise
    raise value
  File "/home/rgarcia/.local/lib/python3.6/site-packages/sqlalchemy/orm/session.py", line 2577, in _flush
    flush_context.execute()
  File "/home/rgarcia/.local/lib/python3.6/site-packages/sqlalchemy/orm/unitofwork.py", line 422, in execute
    rec.execute(self)
  File "/home/rgarcia/.local/lib/python3.6/site-packages/sqlalchemy/orm/unitofwork.py", line 589, in execute
    uow,
  File "/home/rgarcia/.local/lib/python3.6/site-packages/sqlalchemy/orm/persistence.py", line 236, in save_obj
    update,
  File "/home/rgarcia/.local/lib/python3.6/site-packages/sqlalchemy/orm/persistence.py", line 996, in _emit_update_statements
    statement, multiparams
  File "/home/rgarcia/.local/lib/python3.6/site-packages/sqlalchemy/engine/base.py", line 982, in execute
    return meth(self, multiparams, params)
  File "/home/rgarcia/.local/lib/python3.6/site-packages/sqlalchemy/sql/elements.py", line 293, in _execute_on_connection
    return connection._execute_clauseelement(self, multiparams, params)
  File "/home/rgarcia/.local/lib/python3.6/site-packages/sqlalchemy/engine/base.py", line 1101, in _execute_clauseelement
    distilled_params,
  File "/home/rgarcia/.local/lib/python3.6/site-packages/sqlalchemy/engine/base.py", line 1250, in _execute_context
    e, statement, parameters, cursor, context
  File "/home/rgarcia/.local/lib/python3.6/site-packages/sqlalchemy/engine/base.py", line 1476, in _handle_dbapi_exception
    util.raise_from_cause(sqlalchemy_exception, exc_info)
  File "/home/rgarcia/.local/lib/python3.6/site-packages/sqlalchemy/util/compat.py", line 398, in raise_from_cause
    reraise(type(exception), exception, tb=exc_tb, cause=cause)
  File "/home/rgarcia/.local/lib/python3.6/site-packages/sqlalchemy/util/compat.py", line 152, in reraise
    raise value.with_traceback(tb)
  File "/home/rgarcia/.local/lib/python3.6/site-packages/sqlalchemy/engine/base.py", line 1246, in _execute_context
    cursor, statement, parameters, context
  File "/home/rgarcia/.local/lib/python3.6/site-packages/sqlalchemy/engine/default.py", line 588, in do_execute
    cursor.execute(statement, parameters)
sqlalchemy.exc.IntegrityError: (psycopg2.IntegrityError) llave duplicada viola restricción de unicidad «ix_user_username»
DETAIL:  Ya existe la llave (username)=(Reymon).

[SQL: UPDATE "user" SET username=%(username)s, about_me=%(about_me)s WHERE "user".id = %(user_id)s]
[parameters: {'username': 'Reymon', 'about_me': '', 'user_id': 2}]
(Background on this error at: http://sqlalche.me/e/gkpj)
2020-01-28 10:57:11,994 INFO: PREdict startup [in /home/rgarcia/Programs/web-projects/testing-site/app/__init__.py:46]
2020-01-28 11:14:00,220 INFO: PREdict startup [in /home/rgarcia/Programs/web-projects/testing-site/app/__init__.py:46]
2020-01-28 11:14:09,514 INFO: PREdict startup [in /home/rgarcia/Programs/web-projects/testing-site/app/__init__.py:46]
2020-01-28 11:54:06,567 INFO: PREdict startup [in /home/rgarcia/Programs/web-projects/testing-site/app/__init__.py:46]
2020-01-28 12:01:06,682 INFO: PREdict startup [in /home/rgarcia/Programs/web-projects/testing-site/app/__init__.py:46]
2020-01-28 12:01:39,904 INFO: PREdict startup [in /home/rgarcia/Programs/web-projects/testing-site/app/__init__.py:46]
2020-01-28 12:01:43,994 INFO: PREdict startup [in /home/rgarcia/Programs/web-projects/testing-site/app/__init__.py:46]
2020-01-28 12:01:46,276 INFO: PREdict startup [in /home/rgarcia/Programs/web-projects/testing-site/app/__init__.py:46]
2020-01-28 12:02:06,291 INFO: PREdict startup [in /home/rgarcia/Programs/web-projects/testing-site/app/__init__.py:46]
2020-01-28 12:02:41,991 INFO: PREdict startup [in /home/rgarcia/Programs/web-projects/testing-site/app/__init__.py:46]
2020-01-28 12:09:08,664 INFO: PREdict startup [in /home/rgarcia/Programs/web-projects/testing-site/app/__init__.py:46]
2020-01-28 12:11:13,166 INFO: PREdict startup [in /home/rgarcia/Programs/web-projects/testing-site/app/__init__.py:46]
2020-01-28 12:19:55,881 INFO: PREdict startup [in /home/rgarcia/Programs/web-projects/testing-site/app/__init__.py:46]
