2020-01-28 12:19:59,347 ERROR: Exception on /favicon.ico [GET] [in /home/rgarcia/.local/lib/python3.6/site-packages/flask/app.py:1891]
Traceback (most recent call last):
  File "/home/rgarcia/.local/lib/python3.6/site-packages/sqlalchemy/engine/base.py", line 1246, in _execute_context
    cursor, statement, parameters, context
  File "/home/rgarcia/.local/lib/python3.6/site-packages/sqlalchemy/engine/default.py", line 588, in do_execute
    cursor.execute(statement, parameters)
psycopg2.ProgrammingError: no existe la relación «user»
LINE 2: FROM "user" 
             ^


The above exception was the direct cause of the following exception:

Traceback (most recent call last):
  File "/home/rgarcia/.local/lib/python3.6/site-packages/flask/app.py", line 2446, in wsgi_app
    response = self.full_dispatch_request()
  File "/home/rgarcia/.local/lib/python3.6/site-packages/flask/app.py", line 1951, in full_dispatch_request
    rv = self.handle_user_exception(e)
  File "/home/rgarcia/.local/lib/python3.6/site-packages/flask/app.py", line 1820, in handle_user_exception
    reraise(exc_type, exc_value, tb)
  File "/home/rgarcia/.local/lib/python3.6/site-packages/flask/_compat.py", line 39, in reraise
    raise value
  File "/home/rgarcia/.local/lib/python3.6/site-packages/flask/app.py", line 1947, in full_dispatch_request
    rv = self.preprocess_request()
  File "/home/rgarcia/.local/lib/python3.6/site-packages/flask/app.py", line 2241, in preprocess_request
    rv = func()
  File "/home/rgarcia/Programs/web-projects/testing-site/app/routes.py", line 80, in before_request
    if current_user.is_authenticated:
  File "/home/rgarcia/.local/lib/python3.6/site-packages/werkzeug/local.py", line 348, in __getattr__
    return getattr(self._get_current_object(), name)
  File "/home/rgarcia/.local/lib/python3.6/site-packages/werkzeug/local.py", line 307, in _get_current_object
    return self.__local()
  File "/home/rgarcia/.local/lib/python3.6/site-packages/flask_login/utils.py", line 26, in <lambda>
    current_user = LocalProxy(lambda: _get_user())
  File "/home/rgarcia/.local/lib/python3.6/site-packages/flask_login/utils.py", line 335, in _get_user
    current_app.login_manager._load_user()
  File "/home/rgarcia/.local/lib/python3.6/site-packages/flask_login/login_manager.py", line 359, in _load_user
    return self.reload_user()
  File "/home/rgarcia/.local/lib/python3.6/site-packages/flask_login/login_manager.py", line 321, in reload_user
    user = self.user_callback(user_id)
  File "/home/rgarcia/Programs/web-projects/testing-site/app/models.py", line 10, in load_user
    return User.query.get(int(id))
  File "/home/rgarcia/.local/lib/python3.6/site-packages/sqlalchemy/orm/query.py", line 1004, in get
    return self._get_impl(ident, loading.load_on_pk_identity)
  File "/home/rgarcia/.local/lib/python3.6/site-packages/sqlalchemy/orm/query.py", line 1116, in _get_impl
    return db_load_fn(self, primary_key_identity)
  File "/home/rgarcia/.local/lib/python3.6/site-packages/sqlalchemy/orm/loading.py", line 284, in load_on_pk_identity
    return q.one()
  File "/home/rgarcia/.local/lib/python3.6/site-packages/sqlalchemy/orm/query.py", line 3347, in one
    ret = self.one_or_none()
  File "/home/rgarcia/.local/lib/python3.6/site-packages/sqlalchemy/orm/query.py", line 3316, in one_or_none
    ret = list(self)
  File "/home/rgarcia/.local/lib/python3.6/site-packages/sqlalchemy/orm/query.py", line 3389, in __iter__
    return self._execute_and_instances(context)
  File "/home/rgarcia/.local/lib/python3.6/site-packages/sqlalchemy/orm/query.py", line 3414, in _execute_and_instances
    result = conn.execute(querycontext.statement, self._params)
  File "/home/rgarcia/.local/lib/python3.6/site-packages/sqlalchemy/engine/base.py", line 982, in execute
    return meth(self, multiparams, params)
  File "/home/rgarcia/.local/lib/python3.6/site-packages/sqlalchemy/sql/elements.py", line 293, in _execute_on_connection
    return connection._execute_clauseelement(self, multiparams, params)
  File "/home/rgarcia/.local/lib/python3.6/site-packages/sqlalchemy/engine/base.py", line 1101, in _execute_clauseelement
    distilled_params,
  File "/home/rgarcia/.local/lib/python3.6/site-packages/sqlalchemy/engine/base.py", line 1250, in _execute_context
    e, statement, parameters, cursor, context
  File "/home/rgarcia/.local/lib/python3.6/site-packages/sqlalchemy/engine/base.py", line 1476, in _handle_dbapi_exception
    util.raise_from_cause(sqlalchemy_exception, exc_info)
  File "/home/rgarcia/.local/lib/python3.6/site-packages/sqlalchemy/util/compat.py", line 398, in raise_from_cause
    reraise(type(exception), exception, tb=exc_tb, cause=cause)
  File "/home/rgarcia/.local/lib/python3.6/site-packages/sqlalchemy/util/compat.py", line 152, in reraise
    raise value.with_traceback(tb)
  File "/home/rgarcia/.local/lib/python3.6/site-packages/sqlalchemy/engine/base.py", line 1246, in _execute_context
    cursor, statement, parameters, context
  File "/home/rgarcia/.local/lib/python3.6/site-packages/sqlalchemy/engine/default.py", line 588, in do_execute
    cursor.execute(statement, parameters)
sqlalchemy.exc.ProgrammingError: (psycopg2.ProgrammingError) no existe la relación «user»
LINE 2: FROM "user" 
             ^

[SQL: SELECT "user".id AS user_id, "user".username AS user_username, "user".email AS user_email, "user".password_hash AS user_password_hash, "user".about_me AS user_about_me, "user".last_seen AS user_last_seen 
FROM "user" 
WHERE "user".id = %(param_1)s]
[parameters: {'param_1': 2}]
(Background on this error at: http://sqlalche.me/e/f405)
2020-01-28 12:22:00,891 INFO: PREdict startup [in /home/rgarcia/Programs/web-projects/testing-site/app/__init__.py:46]
